Traceback (most recent call last):
  File "/opt/homebrew/lib/python3.11/site-packages/pandas/core/indexes/base.py", line 3790, in get_loc
    return self._engine.get_loc(casted_key)
           ^^^^^^^^^^^^^^^^^^^^^^^^^^^^^^^^
  File "index.pyx", line 152, in pandas._libs.index.IndexEngine.get_loc
  File "index.pyx", line 181, in pandas._libs.index.IndexEngine.get_loc
  File "pandas/_libs/hashtable_class_helper.pxi", line 7080, in pandas._libs.hashtable.PyObjectHashTable.get_item
  File "pandas/_libs/hashtable_class_helper.pxi", line 7088, in pandas._libs.hashtable.PyObjectHashTable.get_item
KeyError: 'discount'

The above exception was the direct cause of the following exception:

Traceback (most recent call last):
  File "/Users/marcoo_sg/Desktop/sem/CSELEC1C/ShopZada_ETL/data_pipeline/data_pipeline_marketing_department/data_pipeline_marketing_department_02_campaign/data_pipeline_marketing_department_02_campaign_remove_symbols.py", line 27, in <module>
    df_campaign_data['discount'] = df_campaign_data['discount'].str.replace('%%', '%')
                                   ~~~~~~~~~~~~~~~~^^^^^^^^^^^^
  File "/opt/homebrew/lib/python3.11/site-packages/pandas/core/frame.py", line 3893, in __getitem__
    indexer = self.columns.get_loc(key)
              ^^^^^^^^^^^^^^^^^^^^^^^^^
  File "/opt/homebrew/lib/python3.11/site-packages/pandas/core/indexes/base.py", line 3797, in get_loc
    raise KeyError(key) from err
KeyError: 'discount'
